Traceback (most recent call last):
  File "/Users/mb312/.virtualenvs/cfd2020/lib/python3.9/site-packages/jupyter_cache/executors/utils.py", line 51, in single_nb_execution
    executenb(
  File "/Users/mb312/.virtualenvs/cfd2020/lib/python3.9/site-packages/nbclient/client.py", line 1117, in execute
    return NotebookClient(nb=nb, resources=resources, km=km, **kwargs).execute()
  File "/Users/mb312/.virtualenvs/cfd2020/lib/python3.9/site-packages/nbclient/util.py", line 78, in wrapped
    return just_run(coro(*args, **kwargs))
  File "/Users/mb312/.virtualenvs/cfd2020/lib/python3.9/site-packages/nbclient/util.py", line 57, in just_run
    return loop.run_until_complete(coro)
  File "/usr/local/Cellar/python@3.9/3.9.7_1/Frameworks/Python.framework/Versions/3.9/lib/python3.9/asyncio/base_events.py", line 642, in run_until_complete
    return future.result()
  File "/Users/mb312/.virtualenvs/cfd2020/lib/python3.9/site-packages/nbclient/client.py", line 558, in async_execute
    await self.async_execute_cell(
  File "/Users/mb312/.virtualenvs/cfd2020/lib/python3.9/site-packages/nbclient/client.py", line 862, in async_execute_cell
    self._check_raise_for_error(cell, exec_reply)
  File "/Users/mb312/.virtualenvs/cfd2020/lib/python3.9/site-packages/nbclient/client.py", line 765, in _check_raise_for_error
    raise CellExecutionError.from_cell_and_msg(cell, exec_reply_content)
nbclient.exceptions.CellExecutionError: An error occurred while executing the following cell:
------------------
# Get the Pandas interface to the StatsModels routines.
import statsmodels.formula.api as smf
------------------

[0;31m---------------------------------------------------------------------------[0m
[0;31mModuleNotFoundError[0m                       Traceback (most recent call last)
[0;32m/var/folders/m6/6wv1nw2s1gj5f3b5zj8pmgmr0000gp/T/ipykernel_63930/1916776351.py[0m in [0;36m<module>[0;34m[0m
[1;32m      1[0m [0;31m# Get the Pandas interface to the StatsModels routines.[0m[0;34m[0m[0;34m[0m[0m
[0;32m----> 2[0;31m [0;32mimport[0m [0mstatsmodels[0m[0;34m.[0m[0mformula[0m[0;34m.[0m[0mapi[0m [0;32mas[0m [0msmf[0m[0;34m[0m[0;34m[0m[0m
[0m
[0;31mModuleNotFoundError[0m: No module named 'statsmodels'
ModuleNotFoundError: No module named 'statsmodels'

